<?xml version="1.0"?>
<robot  xmlns:xacro="http://www.ros.org/wiki/xacro" name="firefighter" >
	
<xacro:property name="width" value=".2" />

  <mujoco>
        <compiler 
        meshdir="../meshes_mujoco/" 
        balanceinertia="true" 
        discardvisual="false" />
  </mujoco>

  <link name="joint1">
    <visual>
      <geometry>
       <mesh filename="package://mercury_mujoco/meshes_mujoco/joint1_jet.stl"/>
      </geometry>
    <origin xyz = "0 0 0 " rpy = " 0 0 3.14"/>
    </visual>
    <collision>
      <geometry>
        <mesh filename="package://mercury_mujoco/meshes_mujoco/joint1_jet.stl"/>
      </geometry>
      <origin xyz = "0 0 0" rpy = "0 0 3.14"/>
    </collision>
  </link>

  <link name="joint2">
    <visual>
      <geometry>
       <mesh filename="package://mercury_mujoco/meshes_mujoco/joint2.stl"/>
      </geometry>
    <origin xyz = "0 0 -0.06096 " rpy = " 0 0 -1.5708"/>
    </visual>
    <collision>
      <geometry>
        <mesh filename="package://mercury_mujoco/meshes_mujoco/joint2.stl"/>
      </geometry>
      <origin xyz = "0 0 -0.06096" rpy = "0 0 -1.5708"/>
    </collision>
  </link>


  <link name="joint3">
    <visual>
      <geometry>
       
       <mesh filename="package://mercury_mujoco/meshes_mujoco/joint3.stl"/>
      </geometry>
    <origin xyz = "0 0 0.03256 " rpy = " 0 -1.5708 0"/>
    </visual>
    <collision>
      <geometry>
        <mesh filename="package://mercury_mujoco/meshes_mujoco/joint3.stl"/>
      </geometry>
      <origin xyz = "0 0 0.03256" rpy = "0 -1.5708 0"/>
    </collision>
  </link>


  <link name="joint4">
    <visual>
      <geometry>
       <mesh filename="package://mercury_mujoco/meshes_mujoco/joint4.stl"/>
      </geometry>
    <origin xyz = "0 0 0.03056 " rpy = " 0 -1.5708 0"/>
    </visual>
    <collision>
      <geometry>
        <mesh filename="package://mercury_mujoco/meshes_mujoco/joint4.stl"/>
      </geometry>
      <origin xyz = "0 0 0.03056" rpy = "0 -1.5708 0"/>
    </collision>
  </link>


  <link name="joint5">
    <visual>
      <geometry>
       <mesh filename="package://mercury_mujoco/meshes_mujoco/joint5.stl"/>
      </geometry>
    <origin xyz = "0 0 -0.03356 " rpy = "-1.5708 0 0"/>
    </visual>
    <collision>
      <geometry>
        <mesh filename="package://mercury_mujoco/meshes_mujoco/joint5.stl"/>
      </geometry>
      <origin xyz = "0 0 -0.03356" rpy = "-1.5708 0 0"/>
    </collision>
  </link>


  <link name="joint6">
    <visual>
      <geometry>
       <mesh filename="package://mercury_mujoco/meshes_mujoco/joint6.stl"/>
      </geometry>
    <origin xyz = "0 0 -0.038 " rpy = " 0 0 0"/>
    </visual>
    <collision>
      <geometry>
        <mesh filename="package://mercury_mujoco/meshes_mujoco/joint6.stl"/>
      </geometry>
      <origin xyz = "0 0 -0.038" rpy = "0 0 0"/>
    </collision>
  </link>


  <link name="joint6_flange">
    <visual>
      <geometry>
       <mesh filename="package://mercury_mujoco/meshes_mujoco/joint7.stl"/>
      </geometry>
    <origin xyz = "0 0 -0.012 " rpy = " 0 0 0"/>
    </visual>
    <collision>
      <geometry>
        <mesh filename="package://mercury_mujoco/meshes_mujoco/joint7.stl"/>
      </geometry>
      <origin xyz = "0 0 -0.012" rpy = "0 0 0"/>
    </collision>
  </link>
  
  
  <joint name="joint2_to_joint1" type="revolute">
    <axis xyz="0 0 1"/>
    <limit effort = "1000.0" lower = "-2.9321" upper = "2.9321" velocity = "0"/>
    <parent link="joint1"/>
    <child link="joint2"/>
    <origin xyz= "0 0 0.15756" rpy = "0 0 0"/>  
  </joint>


  <joint name="joint3_to_joint2" type="revolute">
    <axis xyz="0 0 1"/>
    <limit effort = "1000.0" lower = "-2.0943" upper = "2.0943" velocity = "0"/>
    <parent link="joint2"/>
    <child link="joint3"/>
    <origin xyz= "0 0 -0.001" rpy = "0 1.5708 -1.5708"/>  
  </joint>


  <joint name="joint4_to_joint3" type="revolute">
    <axis xyz=" 0 0 1"/>
    <limit effort = "1000.0" lower = "-2.6179" upper = "2.6179" velocity = "0"/>
    <parent link="joint3"/>
    <child link="joint4"/>
    <origin xyz= "-0.1104 0 0   " rpy = "0 0 0"/>  
  </joint>


  <joint name="joint5_to_joint4" type="revolute">
    <axis xyz=" 0 0 1"/>
    <limit effort = "1000.0" lower = "-2.5307" upper = "2.5307" velocity = "0"/>
    <parent link="joint4"/>
    <child link="joint5"/>
    <origin xyz= "-0.096 0 0.06462" rpy = "0 0 -1.5708"/>  
  </joint>

  <joint name="joint6_to_joint5" type="revolute">
    <axis xyz="0 0 1"/>
    <limit effort = "1000.0" lower = "-2.8797" upper = "2.8797" velocity = "0"/>
    <parent link="joint5"/>
    <child link="joint6"/>
    <origin xyz= "0 -0.07318 0" rpy = "1.5708 -1.5708 0"/>  
  </joint>

  <joint name="joint7_to_joint6" type="revolute">
    <axis xyz="0 0 1"/>
    <limit effort = "1000.0" lower = "-3.14" upper = "3.14159" velocity = "0"/>
    <parent link="joint6"/>
    <child link="joint6_flange"/>
    <origin xyz= "0 0.0456 0" rpy = "-1.5708 0 0"/>  
  </joint>



</robot>

